
Error message :
Traceback (most recent call last):
  File "d:\User\lubin\Documents\#Programmation\python\bot discord\yokai bot\script\main.py", line 722, in medallium
    await ctx.send(view=dropdown())
                        ^^^^^^^^^^
TypeError: 'Inv_dropdown_view' object is not callable


- Nom d'utilisateur / id : __hubble/882241177578004542
- Heure de l'erreur : 2025-03-16 16:54:49
- Commande qui a caus√© l'erreur : medallium