
Error message :
Traceback (most recent call last):
  File "d:\User\lubin\Documents\#Programmation\python\bot discord\yokai bot\script\main.py", line 484, in yokai
    brute_inventory = await get_inv(ctx.author.id)
                      ^^^^^^^^^^^^^^^^^^^^^^^^^^^^
  File "d:\User\lubin\Documents\#Programmation\python\bot discord\yokai bot\script\main.py", line 58, in get_inv
    data = json.load(f)
           ^^^^^^^^^^^^
  File "C:\Users\User\AppData\Local\Programs\Python\Python312\Lib\json\__init__.py", line 293, in load
    return loads(fp.read(),
           ^^^^^^^^^^^^^^^^
  File "C:\Users\User\AppData\Local\Programs\Python\Python312\Lib\json\__init__.py", line 346, in loads
    return _default_decoder.decode(s)
           ^^^^^^^^^^^^^^^^^^^^^^^^^^
  File "C:\Users\User\AppData\Local\Programs\Python\Python312\Lib\json\decoder.py", line 337, in decode
    obj, end = self.raw_decode(s, idx=_w(s, 0).end())
               ^^^^^^^^^^^^^^^^^^^^^^^^^^^^^^^^^^^^^^
  File "C:\Users\User\AppData\Local\Programs\Python\Python312\Lib\json\decoder.py", line 355, in raw_decode
    raise JSONDecodeError("Expecting value", s, err.value) from None
json.decoder.JSONDecodeError: Expecting value: line 1 column 1 (char 0)


- Nom d'utilisateur / id : __hubble/882241177578004542
- Heure de l'erreur : 2025-03-02 15:13:08
- Commande qui a caus√© l'erreur : yokai